Traceback (most recent call last):
  File "/Users/williamnickols/Documents/GitHub/vscode/extensions/erdos-python/python_files/shell_exec.py", line 25, in <module>
    subprocess.check_call(shell_args, stdout=sys.stdout, stderr=sys.stderr)
    ~~~~~~~~~~~~~~~~~~~~~^^^^^^^^^^^^^^^^^^^^^^^^^^^^^^^^^^^^^^^^^^^^^^^^^^
  File "/opt/homebrew/Cellar/python@3.13/3.13.5/Frameworks/Python.framework/Versions/3.13/lib/python3.13/subprocess.py", line 414, in check_call
    retcode = call(*popenargs, **kwargs)
  File "/opt/homebrew/Cellar/python@3.13/3.13.5/Frameworks/Python.framework/Versions/3.13/lib/python3.13/subprocess.py", line 395, in call
    with Popen(*popenargs, **kwargs) as p:
         ~~~~~^^^^^^^^^^^^^^^^^^^^^^
  File "/opt/homebrew/Cellar/python@3.13/3.13.5/Frameworks/Python.framework/Versions/3.13/lib/python3.13/subprocess.py", line 1005, in __init__
    errread, errwrite) = self._get_handles(stdin, stdout, stderr)
                         ~~~~~~~~~~~~~~~~~^^^^^^^^^^^^^^^^^^^^^^^
  File "/opt/homebrew/Cellar/python@3.13/3.13.5/Frameworks/Python.framework/Versions/3.13/lib/python3.13/subprocess.py", line 1741, in _get_handles
    c2pwrite = stdout.fileno()
io.UnsupportedOperation: fileno
