Traceback (most recent call last):
  File "/Users/williamnickols/Documents/GitHub/vscode/extensions/erdos-python/python_files/shell_exec.py", line 25, in <module>
    subprocess.check_call(shell_args, stdout=sys.stdout, stderr=sys.stderr)
  File "/Library/Frameworks/Python.framework/Versions/3.11/lib/python3.11/subprocess.py", line 408, in check_call
    retcode = call(*popenargs, **kwargs)
              ^^^^^^^^^^^^^^^^^^^^^^^^^^
  File "/Library/Frameworks/Python.framework/Versions/3.11/lib/python3.11/subprocess.py", line 389, in call
    with Popen(*popenargs, **kwargs) as p:
         ^^^^^^^^^^^^^^^^^^^^^^^^^^^
  File "/Library/Frameworks/Python.framework/Versions/3.11/lib/python3.11/subprocess.py", line 992, in __init__
    errread, errwrite) = self._get_handles(stdin, stdout, stderr)
                         ^^^^^^^^^^^^^^^^^^^^^^^^^^^^^^^^^^^^^^^^
  File "/Library/Frameworks/Python.framework/Versions/3.11/lib/python3.11/subprocess.py", line 1723, in _get_handles
    c2pwrite = stdout.fileno()
               ^^^^^^^^^^^^^^^
io.UnsupportedOperation: fileno
